Workbook

Sheet Leia-me
A1: PLANILHA DE DADOS — OCUPAÇÃO DE POSTES POR CABOS DE TELECOMUNICAÇÕES
A3: Células AMARELAS = você preenche. Células AZUIS = calculadas (não editar).
A4: Sem nomes: postes T1-01, T1-02…; trechos T1…T4; provedores A, B, C…
A6: Postes — uma linha por poste (ficha F2). Altura: preencha a medida direta (col. H)
A7: OU distância horizontal + ângulo + altura dos olhos (cols. I-K).
A8: Equipes — observações de equipes de telecom (ficha F3).
A9: Fotos — registro fotográfico (ficha F5).
A10: Resumo — totais e percentuais automáticos.
A11: Referencia — limites usados nas comparações. CONFIRA na NBR 15214 ou na norma da
A12: distribuidora e ajuste se necessário: os cálculos se atualizam.
A14: A altura que conta é a do ponto mais baixo do cabo, normalmente o meio do vão.

Sheet Postes
A1: Poste | B1: Trecho | C1: Data | D1: Local do vão | E1: Estrutura elétrica | F1: Nº cabos telecom | G1: Nº pontos de fixação | H1: Altura mín. meio do vão — medida direta (m) | I1: Dist. horizontal (m) [método ângulo] | J1: Ângulo de visada (°) | K1: Altura dos olhos (m) | L1: Altura considerada (m) | M1: Limite (m) | N1: Altura OK? | O1: Altura do neutro no poste (m) | P1: Altura telecom mais alto no poste (m) | Q1: Afastamento telecom–neutro (m) | R1: Afastamento OK? | S1: Plaqueta em todos os cabos? | T1: Sobra enrolada no poste? | U1: Caixa de emenda < 2 m do poste? | V1: Equipamento ativo no poste? | W1: Cabo solto/caído/abandonado? | X1: Cabo encostando na rede/ferragem? | Y1: Poste danificado/inclinado? | Z1: Obstrução da subida | AA1: Nº de não conformidades | AB1: Poste irregular? | AC1: Nº das fotos | AD1: Observações
L2: =IF(H2<>"",H2,IF(AND(I2<>"",J2<>""),ROUND(I2*TAN(RADIANS(J2))+IF(K2="",1.6,K2),2),"")) | M2: =IF(D2="","",IFERROR(IF(VLOOKUP(D2,Referencia!$A$2:$B$5,2,FALSE)="","",VLOOKUP(D2,Referencia!$A$2:$B$5,2,FALSE)),"")) | N2: =IF(OR(L2="",M2=""),"",IF(L2>=M2,"C","NC")) | Q2: =IF(OR(O2="",P2=""),"",ROUND(O2-P2,2)) | R2: =IF(Q2="","",IF(Q2>=Referencia!$B$8,"C","NC")) | AA2: =IF(F2="","",(N2="NC")+(R2="NC")+(S2="Não")+(S2="Parcial")+(T2="Sim")+(U2="Sim")+(V2="Sim")+(W2="Sim")+(X2="Sim")) | AB2: =IF(AA2="","",IF(AA2>0,"Sim","Não"))
L3: =IF(H3<>"",H3,IF(AND(I3<>"",J3<>""),ROUND(I3*TAN(RADIANS(J3))+IF(K3="",1.6,K3),2),"")) | M3: =IF(D3="","",IFERROR(IF(VLOOKUP(D3,Referencia!$A$2:$B$5,2,FALSE)="","",VLOOKUP(D3,Referencia!$A$2:$B$5,2,FALSE)),"")) | N3: =IF(OR(L3="",M3=""),"",IF(L3>=M3,"C","NC")) | Q3: =IF(OR(O3="",P3=""),"",ROUND(O3-P3,2)) | R3: =IF(Q3="","",IF(Q3>=Referencia!$B$8,"C","NC")) | AA3: =IF(F3="","",(N3="NC")+(R3="NC")+(S3="Não")+(S3="Parcial")+(T3="Sim")+(U3="Sim")+(V3="Sim")+(W3="Sim")+(X3="Sim")) | AB3: =IF(AA3="","",IF(AA3>0,"Sim","Não"))
L4: =IF(H4<>"",H4,IF(AND(I4<>"",J4<>""),ROUND(I4*TAN(RADIANS(J4))+IF(K4="",1.6,K4),2),"")) | M4: =IF(D4="","",IFERROR(IF(VLOOKUP(D4,Referencia!$A$2:$B$5,2,FALSE)="","",VLOOKUP(D4,Referencia!$A$2:$B$5,2,FALSE)),"")) | N4: =IF(OR(L4="",M4=""),"",IF(L4>=M4,"C","NC")) | Q4: =IF(OR(O4="",P4=""),"",ROUND(O4-P4,2)) | R4: =IF(Q4="","",IF(Q4>=Referencia!$B$8,"C","NC")) | AA4: =IF(F4="","",(N4="NC")+(R4="NC")+(S4="Não")+(S4="Parcial")+(T4="Sim")+(U4="Sim")+(V4="Sim")+(W4="Sim")+(X4="Sim")) | AB4: =IF(AA4="","",IF(AA4>0,"Sim","Não"))
L5: =IF(H5<>"",H5,IF(AND(I5<>"",J5<>""),ROUND(I5*TAN(RADIANS(J5))+IF(K5="",1.6,K5),2),"")) | M5: =IF(D5="","",IFERROR(IF(VLOOKUP(D5,Referencia!$A$2:$B$5,2,FALSE)="","",VLOOKUP(D5,Referencia!$A$2:$B$5,2,FALSE)),"")) | N5: =IF(OR(L5="",M5=""),"",IF(L5>=M5,"C","NC")) | Q5: =IF(OR(O5="",P5=""),"",ROUND(O5-P5,2)) | R5: =IF(Q5="","",IF(Q5>=Referencia!$B$8,"C","NC")) | AA5: =IF(F5="","",(N5="NC")+(R5="NC")+(S5="Não")+(S5="Parcial")+(T5="Sim")+(U5="Sim")+(V5="Sim")+(W5="Sim")+(X5="Sim")) | AB5: =IF(AA5="","",IF(AA5>0,"Sim","Não"))
L6: =IF(H6<>"",H6,IF(AND(I6<>"",J6<>""),ROUND(I6*TAN(RADIANS(J6))+IF(K6="",1.6,K6),2),"")) | M6: =IF(D6="","",IFERROR(IF(VLOOKUP(D6,Referencia!$A$2:$B$5,2,FALSE)="","",VLOOKUP(D6,Referencia!$A$2:$B$5,2,FALSE)),"")) | N6: =IF(OR(L6="",M6=""),"",IF(L6>=M6,"C","NC")) | Q6: =IF(OR(O6="",P6=""),"",ROUND(O6-P6,2)) | R6: =IF(Q6="","",IF(Q6>=Referencia!$B$8,"C","NC")) | AA6: =IF(F6="","",(N6="NC")+(R6="NC")+(S6="Não")+(S6="Parcial")+(T6="Sim")+(U6="Sim")+(V6="Sim")+(W6="Sim")+(X6="Sim")) | AB6: =IF(AA6="","",IF(AA6>0,"Sim","Não"))
L7: =IF(H7<>"",H7,IF(AND(I7<>"",J7<>""),ROUND(I7*TAN(RADIANS(J7))+IF(K7="",1.6,K7),2),"")) | M7: =IF(D7="","",IFERROR(IF(VLOOKUP(D7,Referencia!$A$2:$B$5,2,FALSE)="","",VLOOKUP(D7,Referencia!$A$2:$B$5,2,FALSE)),"")) | N7: =IF(OR(L7="",M7=""),"",IF(L7>=M7,"C","NC")) | Q7: =IF(OR(O7="",P7=""),"",ROUND(O7-P7,2)) | R7: =IF(Q7="","",IF(Q7>=Referencia!$B$8,"C","NC")) | AA7: =IF(F7="","",(N7="NC")+(R7="NC")+(S7="Não")+(S7="Parcial")+(T7="Sim")+(U7="Sim")+(V7="Sim")+(W7="Sim")+(X7="Sim")) | AB7: =IF(AA7="","",IF(AA7>0,"Sim","Não"))
L8: =IF(H8<>"",H8,IF(AND(I8<>"",J8<>""),ROUND(I8*TAN(RADIANS(J8))+IF(K8="",1.6,K8),2),"")) | M8: =IF(D8="","",IFERROR(IF(VLOOKUP(D8,Referencia!$A$2:$B$5,2,FALSE)="","",VLOOKUP(D8,Referencia!$A$2:$B$5,2,FALSE)),"")) | N8: =IF(OR(L8="",M8=""),"",IF(L8>=M8,"C","NC")) | Q8: =IF(OR(O8="",P8=""),"",ROUND(O8-P8,2)) | R8: =IF(Q8="","",IF(Q8>=Referencia!$B$8,"C","NC")) | AA8: =IF(F8="","",(N8="NC")+(R8="NC")+(S8="Não")+(S8="Parcial")+(T8="Sim")+(U8="Sim")+(V8="Sim")+(W8="Sim")+(X8="Sim")) | AB8: =IF(AA8="","",IF(AA8>0,"Sim","Não"))
L9: =IF(H9<>"",H9,IF(AND(I9<>"",J9<>""),ROUND(I9*TAN(RADIANS(J9))+IF(K9="",1.6,K9),2),"")) | M9: =IF(D9="","",IFERROR(IF(VLOOKUP(D9,Referencia!$A$2:$B$5,2,FALSE)="","",VLOOKUP(D9,Referencia!$A$2:$B$5,2,FALSE)),"")) | N9: =IF(OR(L9="",M9=""),"",IF(L9>=M9,"C","NC")) | Q9: =IF(OR(O9="",P9=""),"",ROUND(O9-P9,2)) | R9: =IF(Q9="","",IF(Q9>=Referencia!$B$8,"C","NC")) | AA9: =IF(F9="","",(N9="NC")+(R9="NC")+(S9="Não")+(S9="Parcial")+(T9="Sim")+(U9="Sim")+(V9="Sim")+(W9="Sim")+(X9="Sim")) | AB9: =IF(AA9="","",IF(AA9>0,"Sim","Não"))
L10: =IF(H10<>"",H10,IF(AND(I10<>"",J10<>""),ROUND(I10*TAN(RADIANS(J10))+IF(K10="",1.6,K10),2),"")) | M10: =IF(D10="","",IFERROR(IF(VLOOKUP(D10,Referencia!$A$2:$B$5,2,FALSE)="","",VLOOKUP(D10,Referencia!$A$2:$B$5,2,FALSE)),"")) | N10: =IF(OR(L10="",M10=""),"",IF(L10>=M10,"C","NC")) | Q10: =IF(OR(O10="",P10=""),"",ROUND(O10-P10,2)) | R10: =IF(Q10="","",IF(Q10>=Referencia!$B$8,"C","NC")) | AA10: =IF(F10="","",(N10="NC")+(R10="NC")+(S10="Não")+(S10="Parcial")+(T10="Sim")+(U10="Sim")+(V10="Sim")+(W10="Sim")+(X10="Sim")) | AB10: =IF(AA10="","",IF(AA10>0,"Sim","Não"))
L11: =IF(H11<>"",H11,IF(AND(I11<>"",J11<>""),ROUND(I11*TAN(RADIANS(J11))+IF(K11="",1.6,K11),2),"")) | M11: =IF(D11="","",IFERROR(IF(VLOOKUP(D11,Referencia!$A$2:$B$5,2,FALSE)="","",VLOOKUP(D11,Referencia!$A$2:$B$5,2,FALSE)),"")) | N11: =IF(OR(L11="",M11=""),"",IF(L11>=M11,"C","NC")) | Q11: =IF(OR(O11="",P11=""),"",ROUND(O11-P11,2)) | R11: =IF(Q11="","",IF(Q11>=Referencia!$B$8,"C","NC")) | AA11: =IF(F11="","",(N11="NC")+(R11="NC")+(S11="Não")+(S11="Parcial")+(T11="Sim")+(U11="Sim")+(V11="Sim")+(W11="Sim")+(X11="Sim")) | AB11: =IF(AA11="","",IF(AA11>0,"Sim","Não"))
L12: =IF(H12<>"",H12,IF(AND(I12<>"",J12<>""),ROUND(I12*TAN(RADIANS(J12))+IF(K12="",1.6,K12),2),"")) | M12: =IF(D12="","",IFERROR(IF(VLOOKUP(D12,Referencia!$A$2:$B$5,2,FALSE)="","",VLOOKUP(D12,Referencia!$A$2:$B$5,2,FALSE)),"")) | N12: =IF(OR(L12="",M12=""),"",IF(L12>=M12,"C","NC")) | Q12: =IF(OR(O12="",P12=""),"",ROUND(O12-P12,2)) | R12: =IF(Q12="","",IF(Q12>=Referencia!$B$8,"C","NC")) | AA12: =IF(F12="","",(N12="NC")+(R12="NC")+(S12="Não")+(S12="Parcial")+(T12="Sim")+(U12="Sim")+(V12="Sim")+(W12="Sim")+(X12="Sim")) | AB12: =IF(AA12="","",IF(AA12>0,"Sim","Não"))
L13: =IF(H13<>"",H13,IF(AND(I13<>"",J13<>""),ROUND(I13*TAN(RADIANS(J13))+IF(K13="",1.6,K13),2),"")) | M13: =IF(D13="","",IFERROR(IF(VLOOKUP(D13,Referencia!$A$2:$B$5,2,FALSE)="","",VLOOKUP(D13,Referencia!$A$2:$B$5,2,FALSE)),"")) | N13: =IF(OR(L13="",M13=""),"",IF(L13>=M13,"C","NC")) | Q13: =IF(OR(O13="",P13=""),"",ROUND(O13-P13,2)) | R13: =IF(Q13="","",IF(Q13>=Referencia!$B$8,"C","NC")) | AA13: =IF(F13="","",(N13="NC")+(R13="NC")+(S13="Não")+(S13="Parcial")+(T13="Sim")+(U13="Sim")+(V13="Sim")+(W13="Sim")+(X13="Sim")) | AB13: =IF(AA13="","",IF(AA13>0,"Sim","Não"))
... L301: =IF(H301<>"",H301,IF(AND(I301<>"",J301<>""),ROUND(I301*TAN(RADIANS(J301))+IF(K301="",1.6,K301),2),"")) | M301: =IF(D301="","",IFERROR(IF(VLOOKUP(D301,Referencia!$A$2:$B$5,2,FALSE)="","",VLOOKUP(D301,Referencia!$A$2:$B$5,2,FALSE)),"")) | N301: =IF(OR(L301="",M301=""),"",IF(L301>=M301,"C","NC")) | Q301: =IF(OR(O301="",P301=""),"",ROUND(O301-P301,2)) | R301: =IF(Q301="","",IF(Q301>=Referencia!$B$8,"C","NC")) | AA301: =IF(F301="","",(N301="NC")+(R301="NC")+(S301="Não")+(S301="Parcial")+(T301="Sim")+(U301="Sim")+(V301="Sim")+(W301="Sim")+(X301="Sim")) | AB301: =IF(AA301="","",IF(AA301>0,"Sim","Não"))

Sheet Resumo
A1: GERAL
A2: Postes levantados | B2: =COUNT(Postes!$F$2:$F$301)
A3: Postes com pelo menos 1 não conformidade | B3: =COUNTIF(Postes!$AB$2:$AB$301,"Sim")
A4: % de postes irregulares | B4: =IFERROR(COUNTIF(Postes!$AB$2:$AB$301,"Sim")/COUNT(Postes!$F$2:$F$301),"")
A5: Média de cabos de telecom por poste | B5: =IFERROR(ROUND(AVERAGE(Postes!$F$2:$F$301),1),"")
A6: Máximo de cabos em um poste | B6: =IFERROR(MAX(Postes!$F$2:$F$301),"")
A7: Média de pontos de fixação por poste | B7: =IFERROR(ROUND(AVERAGE(Postes!$G$2:$G$301),1),"")
A9: ALTURA AO SOLO (vãos)
A10: Vãos avaliados | B10: =COUNTIF(Postes!$N$2:$N$301,"C")+COUNTIF(Postes!$N$2:$N$301,"NC")
A11: Vãos abaixo da altura mínima | B11: =COUNTIF(Postes!$N$2:$N$301,"NC")
A12: % de vãos abaixo da altura mínima | B12: =IFERROR(COUNTIF(Postes!$N$2:$N$301,"NC")/(COUNTIF(Postes!$N$2:$N$301,"C")+COUNTIF(Postes!$N$2:$N$301,"NC")),"")
A13: Menor altura encontrada (m) | B13: =IFERROR(IF(COUNT(Postes!$L$2:$L$301)=0,"",MIN(Postes!$L$2:$L$301)),"")
A15: AFASTAMENTO TELECOM – REDE ELÉTRICA
A16: Postes avaliados | B16: =COUNTIF(Postes!$R$2:$R$301,"C")+COUNTIF(Postes!$R$2:$R$301,"NC")
A17: Postes com afastamento abaixo do mínimo | B17: =COUNTIF(Postes!$R$2:$R$301,"NC")
A18: % abaixo do mínimo | B18: =IFERROR(COUNTIF(Postes!$R$2:$R$301,"NC")/(COUNTIF(Postes!$R$2:$R$301,"C")+COUNTIF(Postes!$R$2:$R$301,"NC")),"")
A19: Menor afastamento encontrado (m) | B19: =IFERROR(IF(COUNT(Postes!$Q$2:$Q$301)=0,"",MIN(Postes!$Q$2:$Q$301)),"")
A21: FREQUÊNCIA DAS IRREGULARIDADES (nº de postes)
A22: Sem plaqueta (não ou parcial) | B22: =COUNTIF(Postes!$S$2:$S$301,"Não")+COUNTIF(Postes!$S$2:$S$301,"Parcial")
A23: Sobra de cabo enrolada no poste | B23: =COUNTIF(Postes!$T$2:$T$301,"Sim")
A24: Caixa de emenda a menos de 2 m do poste | B24: =COUNTIF(Postes!$U$2:$U$301,"Sim")
A25: Equipamento ativo no poste | B25: =COUNTIF(Postes!$V$2:$V$301,"Sim")
A26: Cabo solto, caído ou abandonado | B26: =COUNTIF(Postes!$W$2:$W$301,"Sim")
A27: Cabo encostando na rede ou ferragem | B27: =COUNTIF(Postes!$X$2:$X$301,"Sim")
A28: Poste danificado ou inclinado | B28: =COUNTIF(Postes!$Y$2:$Y$301,"Sim")
A30: OBSTRUÇÃO DA SUBIDA (risco ao eletricista)
A31: Postes com obstrução alta | B31: =COUNTIF(Postes!$Z$2:$Z$301,"Alta")
A32: Média de cabos nos postes com obstrução alta | B32: =IFERROR(ROUND(AVERAGEIF(Postes!$Z$2:$Z$301,"Alta",Postes!$F$2:$F$301),1),"")
A33: Média de cabos nos postes com obstrução baixa | B33: =IFERROR(ROUND(AVERAGEIF(Postes!$Z$2:$Z$301,"Baixa",Postes!$F$2:$F$301),1),"")
A35: EQUIPES DE TELECOM OBSERVADAS
A36: Equipes observadas | B36: =COUNTA(Equipes!A2:A41)
A37: Sem sinalização viária (NC) | B37: =COUNTIF(Equipes!F2:F41,"NC")
A38: Escada apoiada nos cabos / sem estabilização (NC) | B38: =COUNTIF(Equipes!G2:G41,"NC")
A39: Sem conexão acima de 2 m (NC) | B39: =COUNTIF(Equipes!I2:I41,"NC")
A41: POR TRECHO
A42: Trecho | B42: Postes | C42: Irregulares | D42: % irregulares | E42: Vãos NC altura | F42: Afast. NC
A43: T1 | B43: =COUNTIFS(Postes!$B$2:$B$301,"T1",Postes!$F$2:$F$301,"<>") | C43: =COUNTIFS(Postes!$B$2:$B$301,"T1",Postes!$AB$2:$AB$301,"Sim") | D43: =IFERROR(C43/B43,"") | E43: =COUNTIFS(Postes!$B$2:$B$301,"T1",Postes!$N$2:$N$301,"NC") | F43: =COUNTIFS(Postes!$B$2:$B$301,"T1",Postes!$R$2:$R$301,"NC")
A44: T2 | B44: =COUNTIFS(Postes!$B$2:$B$301,"T2",Postes!$F$2:$F$301,"<>") | C44: =COUNTIFS(Postes!$B$2:$B$301,"T2",Postes!$AB$2:$AB$301,"Sim") | D44: =IFERROR(C44/B44,"") | E44: =COUNTIFS(Postes!$B$2:$B$301,"T2",Postes!$N$2:$N$301,"NC") | F44: =COUNTIFS(Postes!$B$2:$B$301,"T2",Postes!$R$2:$R$301,"NC")
A45: T3 | B45: =COUNTIFS(Postes!$B$2:$B$301,"T3",Postes!$F$2:$F$301,"<>") | C45: =COUNTIFS(Postes!$B$2:$B$301,"T3",Postes!$AB$2:$AB$301,"Sim") | D45: =IFERROR(C45/B45,"") | E45: =COUNTIFS(Postes!$B$2:$B$301,"T3",Postes!$N$2:$N$301,"NC") | F45: =COUNTIFS(Postes!$B$2:$B$301,"T3",Postes!$R$2:$R$301,"NC")
A46: T4 | B46: =COUNTIFS(Postes!$B$2:$B$301,"T4",Postes!$F$2:$F$301,"<>") | C46: =COUNTIFS(Postes!$B$2:$B$301,"T4",Postes!$AB$2:$AB$301,"Sim") | D46: =IFERROR(C46/B46,"") | E46: =COUNTIFS(Postes!$B$2:$B$301,"T4",Postes!$N$2:$N$301,"NC") | F46: =COUNTIFS(Postes!$B$2:$B$301,"T4",Postes!$R$2:$R$301,"NC")
...

Sheet Referencia
A1: Local do vão | B1: Altura mín. (m) | C1: Fonte / observação
A2: Rua/avenida | B2: 5 | C2: NBR 15214 — conferir
A3: Entrada de veículos | B3: 4.5 | C3: NBR 15214 (entradas de prédios / uso restrito a veículos) — conferir
A4: Rodovia/ferrovia | B4: 6 | C4: 6,00 a 7,00 m conforme a fonte (7,00 em rodovias federais em algumas normas) — conferir
A5: Só pedestres | C5: Preencher com o valor da norma da distribuidora, se houver
A7: Outros requisitos | B7: Valor
A8: Afastamento mín. telecom – neutro (m) | B8: 0.6 | C8: NBR 15214 — conferir
A9: Distância mín. da caixa de emenda/reserva ao poste (m) | B9: 2 | C9: NBR 15214 — registrado na col. U (S/N)
A10: Diâmetro máx. por ponto de fixação (mm) | B10: 65 | C10: NBR 15214 — referência para a discussão

Sheet Equipes
A1: Data | B1: Trecho | C1: Provedor (letra) | D1: Nº pessoas | E1: Atividade | F1: Sinalização viária | G1: Escada apoiada no poste (não nos cabos) e estabilizada | H1: Escada isolante | I1: Conectado acima de 2 m | J1: Pessoa no solo apoiando/controlando trânsito | K1: Distância da rede elétrica | L1: Capacete com jugular, luvas, calçado | M1: Suspensão em chuva/vento | N1: Cabo novo na faixa e com plaqueta | O1: Nº de NC | P1: Obs.
O2: =IF(A2="","",COUNTIF(F2:N2,"NC"))
O3: =IF(A3="","",COUNTIF(F3:N3,"NC"))
O4: =IF(A4="","",COUNTIF(F4:N4,"NC"))
O5: =IF(A5="","",COUNTIF(F5:N5,"NC"))
O6: =IF(A6="","",COUNTIF(F6:N6,"NC"))
O7: =IF(A7="","",COUNTIF(F7:N7,"NC"))
O8: =IF(A8="","",COUNTIF(F8:N8,"NC"))
O9: =IF(A9="","",COUNTIF(F9:N9,"NC"))
O10: =IF(A10="","",COUNTIF(F10:N10,"NC"))
O11: =IF(A11="","",COUNTIF(F11:N11,"NC"))
O12: =IF(A12="","",COUNTIF(F12:N12,"NC"))
O13: =IF(A13="","",COUNTIF(F13:N13,"NC"))
... O41: =IF(A41="","",COUNTIF(F41:N41,"NC"))

Sheet Fotos
A1: Nº foto | B1: Data | C1: Poste/trecho | D1: O que mostra | E1: Desfocar? | F1: Arquivo
